2025-05-15 10:10:49,702 [INFO] Starting YouTube scraping...
2025-05-15 10:10:53,633 [INFO] Successfully stored 50 YouTube videos in the database
2025-05-15 10:27:23,223 [INFO] Starting YouTube scraping...
2025-05-15 10:27:44,606 [ERROR] Error during YouTube scraping: [WinError 10060] A connection attempt failed because the connected party did not properly respond after a period of time, or established connection failed because connected host has failed to respond
2025-05-15 10:27:44,606 [ERROR] Detailed error:
Traceback (most recent call last):
  File "C:\Users\SofiePischl\Documents\01_HdM\10_ML_OPS\TrendAnalyseSocialMedia\src\scheduler\jobs\youtube_scraper.py", line 104, in scrape_youtube_trending
    response = request.execute()
  File "C:\Users\SofiePischl\Documents\01_HdM\10_ML_OPS\TrendAnalyseSocialMedia\venv\Lib\site-packages\googleapiclient\_helpers.py", line 130, in positional_wrapper
    return wrapped(*args, **kwargs)
  File "C:\Users\SofiePischl\Documents\01_HdM\10_ML_OPS\TrendAnalyseSocialMedia\venv\Lib\site-packages\googleapiclient\http.py", line 923, in execute
    resp, content = _retry_request(
                    ~~~~~~~~~~~~~~^
        http,
        ^^^^^
    ...<7 lines>...
        headers=self.headers,
        ^^^^^^^^^^^^^^^^^^^^^
    )
    ^
  File "C:\Users\SofiePischl\Documents\01_HdM\10_ML_OPS\TrendAnalyseSocialMedia\venv\Lib\site-packages\googleapiclient\http.py", line 222, in _retry_request
    raise exception
  File "C:\Users\SofiePischl\Documents\01_HdM\10_ML_OPS\TrendAnalyseSocialMedia\venv\Lib\site-packages\googleapiclient\http.py", line 191, in _retry_request
    resp, content = http.request(uri, method, *args, **kwargs)
                    ~~~~~~~~~~~~^^^^^^^^^^^^^^^^^^^^^^^^^^^^^^
  File "C:\Users\SofiePischl\Documents\01_HdM\10_ML_OPS\TrendAnalyseSocialMedia\venv\Lib\site-packages\httplib2\__init__.py", line 1724, in request
    (response, content) = self._request(
                          ~~~~~~~~~~~~~^
        conn, authority, uri, request_uri, method, body, headers, redirections, cachekey,
        ^^^^^^^^^^^^^^^^^^^^^^^^^^^^^^^^^^^^^^^^^^^^^^^^^^^^^^^^^^^^^^^^^^^^^^^^^^^^^^^^^
    )
    ^
  File "C:\Users\SofiePischl\Documents\01_HdM\10_ML_OPS\TrendAnalyseSocialMedia\venv\Lib\site-packages\httplib2\__init__.py", line 1444, in _request
    (response, content) = self._conn_request(conn, request_uri, method, body, headers)
                          ~~~~~~~~~~~~~~~~~~^^^^^^^^^^^^^^^^^^^^^^^^^^^^^^^^^^^^^^^^^^
  File "C:\Users\SofiePischl\Documents\01_HdM\10_ML_OPS\TrendAnalyseSocialMedia\venv\Lib\site-packages\httplib2\__init__.py", line 1366, in _conn_request
    conn.connect()
    ~~~~~~~~~~~~^^
  File "C:\Users\SofiePischl\Documents\01_HdM\10_ML_OPS\TrendAnalyseSocialMedia\venv\Lib\site-packages\httplib2\__init__.py", line 1156, in connect
    sock.connect((self.host, self.port))
    ~~~~~~~~~~~~^^^^^^^^^^^^^^^^^^^^^^^^
TimeoutError: [WinError 10060] A connection attempt failed because the connected party did not properly respond after a period of time, or established connection failed because connected host has failed to respond
2025-05-15 10:28:50,858 [INFO] Starting YouTube scraping...
2025-05-15 10:29:12,127 [ERROR] Error during YouTube scraping: [WinError 10060] A connection attempt failed because the connected party did not properly respond after a period of time, or established connection failed because connected host has failed to respond
2025-05-15 10:29:12,128 [ERROR] Detailed error:
Traceback (most recent call last):
  File "C:\Users\SofiePischl\Documents\01_HdM\10_ML_OPS\TrendAnalyseSocialMedia\src\scheduler\jobs\youtube_scraper.py", line 104, in scrape_youtube_trending
    response = request.execute()
  File "C:\Users\SofiePischl\Documents\01_HdM\10_ML_OPS\TrendAnalyseSocialMedia\venv\Lib\site-packages\googleapiclient\_helpers.py", line 130, in positional_wrapper
    return wrapped(*args, **kwargs)
  File "C:\Users\SofiePischl\Documents\01_HdM\10_ML_OPS\TrendAnalyseSocialMedia\venv\Lib\site-packages\googleapiclient\http.py", line 923, in execute
    resp, content = _retry_request(
                    ~~~~~~~~~~~~~~^
        http,
        ^^^^^
    ...<7 lines>...
        headers=self.headers,
        ^^^^^^^^^^^^^^^^^^^^^
    )
    ^
  File "C:\Users\SofiePischl\Documents\01_HdM\10_ML_OPS\TrendAnalyseSocialMedia\venv\Lib\site-packages\googleapiclient\http.py", line 222, in _retry_request
    raise exception
  File "C:\Users\SofiePischl\Documents\01_HdM\10_ML_OPS\TrendAnalyseSocialMedia\venv\Lib\site-packages\googleapiclient\http.py", line 191, in _retry_request
    resp, content = http.request(uri, method, *args, **kwargs)
                    ~~~~~~~~~~~~^^^^^^^^^^^^^^^^^^^^^^^^^^^^^^
  File "C:\Users\SofiePischl\Documents\01_HdM\10_ML_OPS\TrendAnalyseSocialMedia\venv\Lib\site-packages\httplib2\__init__.py", line 1724, in request
    (response, content) = self._request(
                          ~~~~~~~~~~~~~^
        conn, authority, uri, request_uri, method, body, headers, redirections, cachekey,
        ^^^^^^^^^^^^^^^^^^^^^^^^^^^^^^^^^^^^^^^^^^^^^^^^^^^^^^^^^^^^^^^^^^^^^^^^^^^^^^^^^
    )
    ^
  File "C:\Users\SofiePischl\Documents\01_HdM\10_ML_OPS\TrendAnalyseSocialMedia\venv\Lib\site-packages\httplib2\__init__.py", line 1444, in _request
    (response, content) = self._conn_request(conn, request_uri, method, body, headers)
                          ~~~~~~~~~~~~~~~~~~^^^^^^^^^^^^^^^^^^^^^^^^^^^^^^^^^^^^^^^^^^
  File "C:\Users\SofiePischl\Documents\01_HdM\10_ML_OPS\TrendAnalyseSocialMedia\venv\Lib\site-packages\httplib2\__init__.py", line 1366, in _conn_request
    conn.connect()
    ~~~~~~~~~~~~^^
  File "C:\Users\SofiePischl\Documents\01_HdM\10_ML_OPS\TrendAnalyseSocialMedia\venv\Lib\site-packages\httplib2\__init__.py", line 1156, in connect
    sock.connect((self.host, self.port))
    ~~~~~~~~~~~~^^^^^^^^^^^^^^^^^^^^^^^^
TimeoutError: [WinError 10060] A connection attempt failed because the connected party did not properly respond after a period of time, or established connection failed because connected host has failed to respond
2025-05-15 10:30:46,447 [INFO] Starting YouTube scraping...
2025-05-15 10:31:07,660 [ERROR] Error during YouTube scraping: [WinError 10060] A connection attempt failed because the connected party did not properly respond after a period of time, or established connection failed because connected host has failed to respond
2025-05-15 10:31:07,660 [ERROR] Detailed error:
Traceback (most recent call last):
  File "C:\Users\SofiePischl\Documents\01_HdM\10_ML_OPS\TrendAnalyseSocialMedia\src\scheduler\jobs\youtube_scraper.py", line 134, in scrape_youtube_trending
    response = request.execute()
  File "C:\Users\SofiePischl\Documents\01_HdM\10_ML_OPS\TrendAnalyseSocialMedia\venv\Lib\site-packages\googleapiclient\_helpers.py", line 130, in positional_wrapper
    return wrapped(*args, **kwargs)
  File "C:\Users\SofiePischl\Documents\01_HdM\10_ML_OPS\TrendAnalyseSocialMedia\venv\Lib\site-packages\googleapiclient\http.py", line 923, in execute
    resp, content = _retry_request(
                    ~~~~~~~~~~~~~~^
        http,
        ^^^^^
    ...<7 lines>...
        headers=self.headers,
        ^^^^^^^^^^^^^^^^^^^^^
    )
    ^
  File "C:\Users\SofiePischl\Documents\01_HdM\10_ML_OPS\TrendAnalyseSocialMedia\venv\Lib\site-packages\googleapiclient\http.py", line 222, in _retry_request
    raise exception
  File "C:\Users\SofiePischl\Documents\01_HdM\10_ML_OPS\TrendAnalyseSocialMedia\venv\Lib\site-packages\googleapiclient\http.py", line 191, in _retry_request
    resp, content = http.request(uri, method, *args, **kwargs)
                    ~~~~~~~~~~~~^^^^^^^^^^^^^^^^^^^^^^^^^^^^^^
  File "C:\Users\SofiePischl\Documents\01_HdM\10_ML_OPS\TrendAnalyseSocialMedia\venv\Lib\site-packages\httplib2\__init__.py", line 1724, in request
    (response, content) = self._request(
                          ~~~~~~~~~~~~~^
        conn, authority, uri, request_uri, method, body, headers, redirections, cachekey,
        ^^^^^^^^^^^^^^^^^^^^^^^^^^^^^^^^^^^^^^^^^^^^^^^^^^^^^^^^^^^^^^^^^^^^^^^^^^^^^^^^^
    )
    ^
  File "C:\Users\SofiePischl\Documents\01_HdM\10_ML_OPS\TrendAnalyseSocialMedia\venv\Lib\site-packages\httplib2\__init__.py", line 1444, in _request
    (response, content) = self._conn_request(conn, request_uri, method, body, headers)
                          ~~~~~~~~~~~~~~~~~~^^^^^^^^^^^^^^^^^^^^^^^^^^^^^^^^^^^^^^^^^^
  File "C:\Users\SofiePischl\Documents\01_HdM\10_ML_OPS\TrendAnalyseSocialMedia\venv\Lib\site-packages\httplib2\__init__.py", line 1366, in _conn_request
    conn.connect()
    ~~~~~~~~~~~~^^
  File "C:\Users\SofiePischl\Documents\01_HdM\10_ML_OPS\TrendAnalyseSocialMedia\venv\Lib\site-packages\httplib2\__init__.py", line 1156, in connect
    sock.connect((self.host, self.port))
    ~~~~~~~~~~~~^^^^^^^^^^^^^^^^^^^^^^^^
TimeoutError: [WinError 10060] A connection attempt failed because the connected party did not properly respond after a period of time, or established connection failed because connected host has failed to respond
2025-05-15 10:32:32,455 [INFO] Starting YouTube scraping for region DE...
2025-05-15 10:32:33,238 [INFO] Successfully fetched trending videos from YouTube API
2025-05-15 10:32:33,239 [INFO] Found 50 trending videos
2025-05-15 10:32:35,939 [INFO] Successfully stored 50 YouTube videos in the database
2025-05-15 10:41:30,782 [INFO] Last scrape was 9.0 minutes ago - waiting
2025-05-15 10:42:52,921 [INFO] Last scrape was 10.3 minutes ago - waiting
2025-05-15 10:42:52,921 [INFO] Last scrape was 10.3 minutes ago - waiting
2025-05-15 10:42:52,921 [INFO] Last scrape was 10.3 minutes ago - waiting
2025-05-15 10:58:10,723 [INFO] Starting YouTube scraping for region DE...
2025-05-15 10:58:11,359 [INFO] Successfully fetched trending videos from YouTube API
2025-05-15 10:58:11,360 [INFO] Found 50 trending videos
2025-05-15 10:58:14,043 [INFO] Successfully stored 50 YouTube videos in the database
2025-05-15 10:59:50,019 [INFO] Last scrape was 1.6 minutes ago - waiting
2025-05-15 10:59:50,019 [INFO] Last scrape was 1.6 minutes ago - waiting
2025-05-15 10:59:50,019 [INFO] Last scrape was 1.6 minutes ago - waiting
2025-05-15 10:59:50,019 [INFO] Last scrape was 1.6 minutes ago - waiting
2025-05-15 11:14:54,856 [INFO] Starting YouTube scraping for region DE...
2025-05-15 11:14:55,308 [INFO] Successfully fetched trending videos from YouTube API
2025-05-15 11:14:55,308 [INFO] Found 50 trending videos
2025-05-15 11:14:57,990 [INFO] Successfully stored 50 YouTube videos in the database
2025-05-15 14:14:18,424 [INFO] Starting YouTube scraping for region DE...
2025-05-15 14:14:39,821 [ERROR] Error during YouTube scraping: [WinError 10060] A connection attempt failed because the connected party did not properly respond after a period of time, or established connection failed because connected host has failed to respond
2025-05-15 14:14:39,822 [ERROR] Detailed error:
Traceback (most recent call last):
  File "c:\Users\SofiePischl\Documents\01_HdM\10_ML_OPS\TrendAnalyseSocialMedia\src\scheduler\jobs\youtube_scraper.py", line 141, in scrape_youtube_trending
    response = request.execute()
  File "C:\Users\SofiePischl\Documents\01_HdM\10_ML_OPS\TrendAnalyseSocialMedia\venv\Lib\site-packages\googleapiclient\_helpers.py", line 130, in positional_wrapper
    return wrapped(*args, **kwargs)
  File "C:\Users\SofiePischl\Documents\01_HdM\10_ML_OPS\TrendAnalyseSocialMedia\venv\Lib\site-packages\googleapiclient\http.py", line 923, in execute
    resp, content = _retry_request(
                    ~~~~~~~~~~~~~~^
        http,
        ^^^^^
    ...<7 lines>...
        headers=self.headers,
        ^^^^^^^^^^^^^^^^^^^^^
    )
    ^
  File "C:\Users\SofiePischl\Documents\01_HdM\10_ML_OPS\TrendAnalyseSocialMedia\venv\Lib\site-packages\googleapiclient\http.py", line 222, in _retry_request
    raise exception
  File "C:\Users\SofiePischl\Documents\01_HdM\10_ML_OPS\TrendAnalyseSocialMedia\venv\Lib\site-packages\googleapiclient\http.py", line 191, in _retry_request
    resp, content = http.request(uri, method, *args, **kwargs)
                    ~~~~~~~~~~~~^^^^^^^^^^^^^^^^^^^^^^^^^^^^^^
  File "C:\Users\SofiePischl\Documents\01_HdM\10_ML_OPS\TrendAnalyseSocialMedia\venv\Lib\site-packages\httplib2\__init__.py", line 1724, in request
    (response, content) = self._request(
                          ~~~~~~~~~~~~~^
        conn, authority, uri, request_uri, method, body, headers, redirections, cachekey,
        ^^^^^^^^^^^^^^^^^^^^^^^^^^^^^^^^^^^^^^^^^^^^^^^^^^^^^^^^^^^^^^^^^^^^^^^^^^^^^^^^^
    )
    ^
  File "C:\Users\SofiePischl\Documents\01_HdM\10_ML_OPS\TrendAnalyseSocialMedia\venv\Lib\site-packages\httplib2\__init__.py", line 1444, in _request
    (response, content) = self._conn_request(conn, request_uri, method, body, headers)
                          ~~~~~~~~~~~~~~~~~~^^^^^^^^^^^^^^^^^^^^^^^^^^^^^^^^^^^^^^^^^^
  File "C:\Users\SofiePischl\Documents\01_HdM\10_ML_OPS\TrendAnalyseSocialMedia\venv\Lib\site-packages\httplib2\__init__.py", line 1366, in _conn_request
    conn.connect()
    ~~~~~~~~~~~~^^
  File "C:\Users\SofiePischl\Documents\01_HdM\10_ML_OPS\TrendAnalyseSocialMedia\venv\Lib\site-packages\httplib2\__init__.py", line 1156, in connect
    sock.connect((self.host, self.port))
    ~~~~~~~~~~~~^^^^^^^^^^^^^^^^^^^^^^^^
TimeoutError: [WinError 10060] A connection attempt failed because the connected party did not properly respond after a period of time, or established connection failed because connected host has failed to respond
2025-05-15 14:31:23,268 [INFO] Starting YouTube scraping for region DE...
2025-05-15 14:31:24,131 [INFO] Successfully fetched trending videos from YouTube API
2025-05-15 14:31:24,132 [INFO] Found 50 trending videos
2025-05-15 14:31:26,873 [INFO] Successfully stored 50 YouTube videos in the database
2025-05-15 14:48:09,512 [INFO] Starting YouTube scraping for region DE...
2025-05-15 14:48:30,763 [ERROR] Error during YouTube scraping: [WinError 10060] A connection attempt failed because the connected party did not properly respond after a period of time, or established connection failed because connected host has failed to respond
2025-05-15 14:48:30,763 [ERROR] Detailed error:
Traceback (most recent call last):
  File "C:\Users\SofiePischl\Documents\01_HdM\10_ML_OPS\TrendAnalyseSocialMedia\venv\Lib\site-packages\httplib2\__init__.py", line 1396, in _conn_request
    response = conn.getresponse()
  File "C:\Python313\Lib\http\client.py", line 1430, in getresponse
    response.begin()
    ~~~~~~~~~~~~~~^^
  File "C:\Python313\Lib\http\client.py", line 331, in begin
    version, status, reason = self._read_status()
                              ~~~~~~~~~~~~~~~~~^^
  File "C:\Python313\Lib\http\client.py", line 300, in _read_status
    raise RemoteDisconnected("Remote end closed connection without"
                             " response")
http.client.RemoteDisconnected: Remote end closed connection without response

During handling of the above exception, another exception occurred:

Traceback (most recent call last):
  File "c:\Users\SofiePischl\Documents\01_HdM\10_ML_OPS\TrendAnalyseSocialMedia\src\scheduler\jobs\youtube_scraper.py", line 141, in scrape_youtube_trending
    response = request.execute()
  File "C:\Users\SofiePischl\Documents\01_HdM\10_ML_OPS\TrendAnalyseSocialMedia\venv\Lib\site-packages\googleapiclient\_helpers.py", line 130, in positional_wrapper
    return wrapped(*args, **kwargs)
  File "C:\Users\SofiePischl\Documents\01_HdM\10_ML_OPS\TrendAnalyseSocialMedia\venv\Lib\site-packages\googleapiclient\http.py", line 923, in execute
    resp, content = _retry_request(
                    ~~~~~~~~~~~~~~^
        http,
        ^^^^^
    ...<7 lines>...
        headers=self.headers,
        ^^^^^^^^^^^^^^^^^^^^^
    )
    ^
  File "C:\Users\SofiePischl\Documents\01_HdM\10_ML_OPS\TrendAnalyseSocialMedia\venv\Lib\site-packages\googleapiclient\http.py", line 222, in _retry_request
    raise exception
  File "C:\Users\SofiePischl\Documents\01_HdM\10_ML_OPS\TrendAnalyseSocialMedia\venv\Lib\site-packages\googleapiclient\http.py", line 191, in _retry_request
    resp, content = http.request(uri, method, *args, **kwargs)
                    ~~~~~~~~~~~~^^^^^^^^^^^^^^^^^^^^^^^^^^^^^^
  File "C:\Users\SofiePischl\Documents\01_HdM\10_ML_OPS\TrendAnalyseSocialMedia\venv\Lib\site-packages\httplib2\__init__.py", line 1724, in request
    (response, content) = self._request(
                          ~~~~~~~~~~~~~^
        conn, authority, uri, request_uri, method, body, headers, redirections, cachekey,
        ^^^^^^^^^^^^^^^^^^^^^^^^^^^^^^^^^^^^^^^^^^^^^^^^^^^^^^^^^^^^^^^^^^^^^^^^^^^^^^^^^
    )
    ^
  File "C:\Users\SofiePischl\Documents\01_HdM\10_ML_OPS\TrendAnalyseSocialMedia\venv\Lib\site-packages\httplib2\__init__.py", line 1444, in _request
    (response, content) = self._conn_request(conn, request_uri, method, body, headers)
                          ~~~~~~~~~~~~~~~~~~^^^^^^^^^^^^^^^^^^^^^^^^^^^^^^^^^^^^^^^^^^
  File "C:\Users\SofiePischl\Documents\01_HdM\10_ML_OPS\TrendAnalyseSocialMedia\venv\Lib\site-packages\httplib2\__init__.py", line 1405, in _conn_request
    conn.connect()
    ~~~~~~~~~~~~^^
  File "C:\Users\SofiePischl\Documents\01_HdM\10_ML_OPS\TrendAnalyseSocialMedia\venv\Lib\site-packages\httplib2\__init__.py", line 1156, in connect
    sock.connect((self.host, self.port))
    ~~~~~~~~~~~~^^^^^^^^^^^^^^^^^^^^^^^^
TimeoutError: [WinError 10060] A connection attempt failed because the connected party did not properly respond after a period of time, or established connection failed because connected host has failed to respond
2025-05-15 15:05:13,540 [INFO] Starting YouTube scraping for region DE...
2025-05-15 15:05:14,142 [INFO] Successfully fetched trending videos from YouTube API
2025-05-15 15:05:14,143 [INFO] Found 50 trending videos
2025-05-15 15:05:16,807 [INFO] Successfully stored 50 YouTube videos in the database
2025-05-15 15:33:37,253 [INFO] Starting YouTube scraping for region DE...
2025-05-15 15:33:37,255 [ERROR] Error during YouTube scraping: [WinError 10053] An established connection was aborted by the software in your host machine
2025-05-15 15:33:37,255 [ERROR] Detailed error:
Traceback (most recent call last):
  File "c:\Users\SofiePischl\Documents\01_HdM\10_ML_OPS\TrendAnalyseSocialMedia\src\scheduler\jobs\youtube_scraper.py", line 141, in scrape_youtube_trending
    response = request.execute()
  File "C:\Users\SofiePischl\Documents\01_HdM\10_ML_OPS\TrendAnalyseSocialMedia\venv\Lib\site-packages\googleapiclient\_helpers.py", line 130, in positional_wrapper
    return wrapped(*args, **kwargs)
  File "C:\Users\SofiePischl\Documents\01_HdM\10_ML_OPS\TrendAnalyseSocialMedia\venv\Lib\site-packages\googleapiclient\http.py", line 923, in execute
    resp, content = _retry_request(
                    ~~~~~~~~~~~~~~^
        http,
        ^^^^^
    ...<7 lines>...
        headers=self.headers,
        ^^^^^^^^^^^^^^^^^^^^^
    )
    ^
  File "C:\Users\SofiePischl\Documents\01_HdM\10_ML_OPS\TrendAnalyseSocialMedia\venv\Lib\site-packages\googleapiclient\http.py", line 222, in _retry_request
    raise exception
  File "C:\Users\SofiePischl\Documents\01_HdM\10_ML_OPS\TrendAnalyseSocialMedia\venv\Lib\site-packages\googleapiclient\http.py", line 191, in _retry_request
    resp, content = http.request(uri, method, *args, **kwargs)
                    ~~~~~~~~~~~~^^^^^^^^^^^^^^^^^^^^^^^^^^^^^^
  File "C:\Users\SofiePischl\Documents\01_HdM\10_ML_OPS\TrendAnalyseSocialMedia\venv\Lib\site-packages\httplib2\__init__.py", line 1724, in request
    (response, content) = self._request(
                          ~~~~~~~~~~~~~^
        conn, authority, uri, request_uri, method, body, headers, redirections, cachekey,
        ^^^^^^^^^^^^^^^^^^^^^^^^^^^^^^^^^^^^^^^^^^^^^^^^^^^^^^^^^^^^^^^^^^^^^^^^^^^^^^^^^
    )
    ^
  File "C:\Users\SofiePischl\Documents\01_HdM\10_ML_OPS\TrendAnalyseSocialMedia\venv\Lib\site-packages\httplib2\__init__.py", line 1444, in _request
    (response, content) = self._conn_request(conn, request_uri, method, body, headers)
                          ~~~~~~~~~~~~~~~~~~^^^^^^^^^^^^^^^^^^^^^^^^^^^^^^^^^^^^^^^^^^
  File "C:\Users\SofiePischl\Documents\01_HdM\10_ML_OPS\TrendAnalyseSocialMedia\venv\Lib\site-packages\httplib2\__init__.py", line 1367, in _conn_request
    conn.request(method, request_uri, body, headers)
    ~~~~~~~~~~~~^^^^^^^^^^^^^^^^^^^^^^^^^^^^^^^^^^^^
  File "C:\Python313\Lib\http\client.py", line 1338, in request
    self._send_request(method, url, body, headers, encode_chunked)
    ~~~~~~~~~~~~~~~~~~^^^^^^^^^^^^^^^^^^^^^^^^^^^^^^^^^^^^^^^^^^^^
  File "C:\Python313\Lib\http\client.py", line 1384, in _send_request
    self.endheaders(body, encode_chunked=encode_chunked)
    ~~~~~~~~~~~~~~~^^^^^^^^^^^^^^^^^^^^^^^^^^^^^^^^^^^^^
  File "C:\Python313\Lib\http\client.py", line 1333, in endheaders
    self._send_output(message_body, encode_chunked=encode_chunked)
    ~~~~~~~~~~~~~~~~~^^^^^^^^^^^^^^^^^^^^^^^^^^^^^^^^^^^^^^^^^^^^^
  File "C:\Python313\Lib\http\client.py", line 1093, in _send_output
    self.send(msg)
    ~~~~~~~~~^^^^^
  File "C:\Python313\Lib\http\client.py", line 1057, in send
    self.sock.sendall(data)
    ~~~~~~~~~~~~~~~~~^^^^^^
  File "C:\Python313\Lib\ssl.py", line 1263, in sendall
    v = self.send(byte_view[count:])
  File "C:\Python313\Lib\ssl.py", line 1232, in send
    return self._sslobj.write(data)
           ~~~~~~~~~~~~~~~~~~^^^^^^
ConnectionAbortedError: [WinError 10053] An established connection was aborted by the software in your host machine
2025-05-15 15:50:22,768 [INFO] Starting YouTube scraping for region DE...
2025-05-15 15:50:22,770 [ERROR] Error during YouTube scraping: [WinError 10053] An established connection was aborted by the software in your host machine
2025-05-15 15:50:22,770 [ERROR] Detailed error:
Traceback (most recent call last):
  File "c:\Users\SofiePischl\Documents\01_HdM\10_ML_OPS\TrendAnalyseSocialMedia\src\scheduler\jobs\youtube_scraper.py", line 141, in scrape_youtube_trending
    response = request.execute()
  File "C:\Users\SofiePischl\Documents\01_HdM\10_ML_OPS\TrendAnalyseSocialMedia\venv\Lib\site-packages\googleapiclient\_helpers.py", line 130, in positional_wrapper
    return wrapped(*args, **kwargs)
  File "C:\Users\SofiePischl\Documents\01_HdM\10_ML_OPS\TrendAnalyseSocialMedia\venv\Lib\site-packages\googleapiclient\http.py", line 923, in execute
    resp, content = _retry_request(
                    ~~~~~~~~~~~~~~^
        http,
        ^^^^^
    ...<7 lines>...
        headers=self.headers,
        ^^^^^^^^^^^^^^^^^^^^^
    )
    ^
  File "C:\Users\SofiePischl\Documents\01_HdM\10_ML_OPS\TrendAnalyseSocialMedia\venv\Lib\site-packages\googleapiclient\http.py", line 222, in _retry_request
    raise exception
  File "C:\Users\SofiePischl\Documents\01_HdM\10_ML_OPS\TrendAnalyseSocialMedia\venv\Lib\site-packages\googleapiclient\http.py", line 191, in _retry_request
    resp, content = http.request(uri, method, *args, **kwargs)
                    ~~~~~~~~~~~~^^^^^^^^^^^^^^^^^^^^^^^^^^^^^^
  File "C:\Users\SofiePischl\Documents\01_HdM\10_ML_OPS\TrendAnalyseSocialMedia\venv\Lib\site-packages\httplib2\__init__.py", line 1724, in request
    (response, content) = self._request(
                          ~~~~~~~~~~~~~^
        conn, authority, uri, request_uri, method, body, headers, redirections, cachekey,
        ^^^^^^^^^^^^^^^^^^^^^^^^^^^^^^^^^^^^^^^^^^^^^^^^^^^^^^^^^^^^^^^^^^^^^^^^^^^^^^^^^
    )
    ^
  File "C:\Users\SofiePischl\Documents\01_HdM\10_ML_OPS\TrendAnalyseSocialMedia\venv\Lib\site-packages\httplib2\__init__.py", line 1444, in _request
    (response, content) = self._conn_request(conn, request_uri, method, body, headers)
                          ~~~~~~~~~~~~~~~~~~^^^^^^^^^^^^^^^^^^^^^^^^^^^^^^^^^^^^^^^^^^
  File "C:\Users\SofiePischl\Documents\01_HdM\10_ML_OPS\TrendAnalyseSocialMedia\venv\Lib\site-packages\httplib2\__init__.py", line 1396, in _conn_request
    response = conn.getresponse()
  File "C:\Python313\Lib\http\client.py", line 1430, in getresponse
    response.begin()
    ~~~~~~~~~~~~~~^^
  File "C:\Python313\Lib\http\client.py", line 331, in begin
    version, status, reason = self._read_status()
                              ~~~~~~~~~~~~~~~~~^^
  File "C:\Python313\Lib\http\client.py", line 292, in _read_status
    line = str(self.fp.readline(_MAXLINE + 1), "iso-8859-1")
               ~~~~~~~~~~~~~~~~^^^^^^^^^^^^^^
  File "C:\Python313\Lib\socket.py", line 719, in readinto
    return self._sock.recv_into(b)
           ~~~~~~~~~~~~~~~~~~~~^^^
  File "C:\Python313\Lib\ssl.py", line 1304, in recv_into
    return self.read(nbytes, buffer)
           ~~~~~~~~~^^^^^^^^^^^^^^^^
  File "C:\Python313\Lib\ssl.py", line 1138, in read
    return self._sslobj.read(len, buffer)
           ~~~~~~~~~~~~~~~~~^^^^^^^^^^^^^
ConnectionAbortedError: [WinError 10053] An established connection was aborted by the software in your host machine
2025-05-15 16:33:02,171 [INFO] Starting YouTube scraping for region DE...
2025-05-15 16:33:02,586 [INFO] Successfully fetched trending videos from YouTube API
2025-05-15 16:33:02,587 [INFO] Found 50 trending videos
2025-05-15 16:33:05,363 [INFO] Successfully stored 50 YouTube videos in the database
2025-05-15 16:49:51,107 [INFO] Starting YouTube scraping for region DE...
2025-05-15 16:49:51,538 [INFO] Successfully fetched trending videos from YouTube API
2025-05-15 16:49:51,538 [INFO] Found 50 trending videos
2025-05-15 16:49:54,185 [INFO] Successfully stored 50 YouTube videos in the database
2025-05-15 17:06:40,402 [INFO] Starting YouTube scraping for region DE...
2025-05-15 17:06:40,783 [INFO] Successfully fetched trending videos from YouTube API
2025-05-15 17:06:40,784 [INFO] Found 50 trending videos
2025-05-15 17:06:43,468 [INFO] Successfully stored 50 YouTube videos in the database
2025-05-15 17:18:43,527 [INFO] Last scrape was 12.0 minutes ago - waiting
2025-05-15 17:35:10,948 [INFO] Starting YouTube scraping for region DE...
2025-05-15 17:35:11,653 [INFO] Successfully fetched trending videos from YouTube API
2025-05-15 17:35:11,654 [INFO] Found 50 trending videos
2025-05-15 17:35:14,367 [INFO] Successfully stored 50 YouTube videos in the database
2025-05-15 17:37:17,960 [INFO] Last scrape was 2.1 minutes ago - waiting
2025-05-15 17:38:56,276 [INFO] Last scrape was 3.7 minutes ago - waiting
2025-05-15 18:32:35,318 [INFO] Starting YouTube scraping for region DE...
2025-05-15 18:32:35,738 [INFO] Successfully fetched trending videos from YouTube API
2025-05-15 18:32:35,738 [INFO] Found 50 trending videos
2025-05-15 18:32:38,366 [INFO] Successfully stored 50 YouTube videos in the database
2025-05-15 18:39:13,633 [INFO] Last scrape was 6.6 minutes ago - waiting
2025-05-15 18:42:40,785 [INFO] Last scrape was 10.1 minutes ago - waiting
2025-05-15 18:42:44,095 [INFO] Last scrape was 10.1 minutes ago - waiting
2025-05-15 18:44:59,328 [INFO] Last scrape was 12.4 minutes ago - waiting
2025-05-15 18:56:06,710 [INFO] Starting YouTube scraping for region DE...
2025-05-15 18:56:07,219 [INFO] Successfully fetched trending videos from YouTube API
2025-05-15 18:56:07,219 [INFO] Found 50 trending videos
2025-05-15 18:56:09,861 [ERROR] Error during YouTube scraping: column "url" of relation "youtube_data" does not exist
LINE 5:                             url, scraped_at, trending_date
                                    ^

2025-05-15 18:56:09,861 [ERROR] Detailed error:
Traceback (most recent call last):
  File "C:\Users\SofiePischl\Documents\01_HdM\10_ML_OPS\TrendAnalyseSocialMedia\src\scheduler\jobs\youtube_scraper.py", line 199, in scrape_youtube_trending
    execute_values(cur, insert_query, values)
    ~~~~~~~~~~~~~~^^^^^^^^^^^^^^^^^^^^^^^^^^^
  File "C:\Users\SofiePischl\Documents\01_HdM\10_ML_OPS\TrendAnalyseSocialMedia\venv\Lib\site-packages\psycopg2\extras.py", line 1299, in execute_values
    cur.execute(b''.join(parts))
    ~~~~~~~~~~~^^^^^^^^^^^^^^^^^
psycopg2.errors.UndefinedColumn: column "url" of relation "youtube_data" does not exist
LINE 5:                             url, scraped_at, trending_date
                                    ^

2025-05-15 19:00:13,730 [INFO] Starting YouTube scraping for region DE...
2025-05-15 19:00:14,050 [INFO] Successfully fetched trending videos from YouTube API
2025-05-15 19:00:14,050 [INFO] Found 50 trending videos
2025-05-15 19:00:16,675 [INFO] Successfully stored 50 YouTube videos in the database
2025-05-15 19:03:22,762 [INFO] Starting YouTube scraping for region DE...
2025-05-15 19:03:23,279 [INFO] Successfully fetched trending videos from YouTube API
2025-05-15 19:03:23,279 [INFO] Found 50 trending videos
2025-05-15 19:03:25,833 [ERROR] Error during YouTube scraping: column "url" of relation "youtube_data" does not exist
LINE 5:                             url, scraped_at, trending_date
                                    ^

2025-05-15 19:03:25,834 [ERROR] Detailed error:
Traceback (most recent call last):
  File "C:\Users\SofiePischl\Documents\01_HdM\10_ML_OPS\TrendAnalyseSocialMedia\src\scheduler\jobs\youtube_scraper.py", line 199, in scrape_youtube_trending
    execute_values(cur, insert_query, values)
    ~~~~~~~~~~~~~~^^^^^^^^^^^^^^^^^^^^^^^^^^^
  File "C:\Users\SofiePischl\Documents\01_HdM\10_ML_OPS\TrendAnalyseSocialMedia\venv\Lib\site-packages\psycopg2\extras.py", line 1299, in execute_values
    cur.execute(b''.join(parts))
    ~~~~~~~~~~~^^^^^^^^^^^^^^^^^
psycopg2.errors.UndefinedColumn: column "url" of relation "youtube_data" does not exist
LINE 5:                             url, scraped_at, trending_date
                                    ^

2025-05-15 19:06:45,484 [INFO] Starting YouTube scraping for region DE...
2025-05-15 19:06:45,841 [INFO] Successfully fetched trending videos from YouTube API
2025-05-15 19:06:45,842 [INFO] Found 50 trending videos
2025-05-15 19:06:48,518 [ERROR] Error during YouTube scraping: column "url" of relation "youtube_data" does not exist
LINE 5:                             url, scraped_at, trending_date
                                    ^

2025-05-15 19:06:48,518 [ERROR] Detailed error:
Traceback (most recent call last):
  File "C:\Users\SofiePischl\Documents\01_HdM\10_ML_OPS\TrendAnalyseSocialMedia\src\scheduler\jobs\youtube_scraper.py", line 233, in scrape_youtube_trending
    execute_values(cur, insert_query, values)
    ~~~~~~~~~~~~~~^^^^^^^^^^^^^^^^^^^^^^^^^^^
  File "C:\Users\SofiePischl\Documents\01_HdM\10_ML_OPS\TrendAnalyseSocialMedia\venv\Lib\site-packages\psycopg2\extras.py", line 1299, in execute_values
    cur.execute(b''.join(parts))
    ~~~~~~~~~~~^^^^^^^^^^^^^^^^^
psycopg2.errors.UndefinedColumn: column "url" of relation "youtube_data" does not exist
LINE 5:                             url, scraped_at, trending_date
                                    ^

2025-05-15 19:06:50,522 [ERROR] Error updating YouTube status: column "url" of relation "youtube_data" does not exist
LINE 3: ...lished_at, view_count, like_count, comment_count, url, scrap...
                                                             ^

2025-05-15 19:11:29,596 [INFO] Starting YouTube scraping for region DE...
2025-05-15 19:11:29,980 [INFO] Successfully fetched trending videos from YouTube API
2025-05-15 19:11:29,980 [INFO] Found 50 trending videos
2025-05-15 19:11:32,272 [INFO] Starting YouTube scraping for region DE...
2025-05-15 19:11:32,606 [ERROR] Error during YouTube scraping: column "url" of relation "youtube_data" does not exist
LINE 5:                             url, scraped_at, trending_date
                                    ^

2025-05-15 19:11:32,607 [ERROR] Detailed error:
Traceback (most recent call last):
  File "C:\Users\SofiePischl\Documents\01_HdM\10_ML_OPS\TrendAnalyseSocialMedia\src\scheduler\jobs\youtube_scraper.py", line 199, in scrape_youtube_trending
    PRIMARY KEY (video_id, trending_date)
    ^^^^^^^^^^^^^^^^^^^^^^^^^^^^^^^^^
  File "C:\Users\SofiePischl\Documents\01_HdM\10_ML_OPS\TrendAnalyseSocialMedia\venv\Lib\site-packages\psycopg2\extras.py", line 1299, in execute_values
    cur.execute(b''.join(parts))
    ~~~~~~~~~~~^^^^^^^^^^^^^^^^^
psycopg2.errors.UndefinedColumn: column "url" of relation "youtube_data" does not exist
LINE 5:                             url, scraped_at, trending_date
                                    ^

2025-05-15 19:11:32,623 [INFO] Successfully fetched trending videos from YouTube API
2025-05-15 19:11:32,624 [INFO] Found 50 trending videos
2025-05-15 19:11:35,281 [ERROR] Error during YouTube scraping: column "url" of relation "youtube_data" does not exist
LINE 5:                             url, scraped_at, trending_date
                                    ^

2025-05-15 19:11:35,281 [ERROR] Detailed error:
Traceback (most recent call last):
  File "C:\Users\SofiePischl\Documents\01_HdM\10_ML_OPS\TrendAnalyseSocialMedia\src\scheduler\jobs\youtube_scraper.py", line 233, in scrape_youtube_trending
    execute_values(cur, insert_query, values)
    ~~~~~~~~~~~~~~^^^^^^^^^^^^^^^^^^^^^^^^^^^
  File "C:\Users\SofiePischl\Documents\01_HdM\10_ML_OPS\TrendAnalyseSocialMedia\venv\Lib\site-packages\psycopg2\extras.py", line 1299, in execute_values
    cur.execute(b''.join(parts))
    ~~~~~~~~~~~^^^^^^^^^^^^^^^^^
psycopg2.errors.UndefinedColumn: column "url" of relation "youtube_data" does not exist
LINE 5:                             url, scraped_at, trending_date
                                    ^

2025-05-15 19:11:37,239 [ERROR] Error updating YouTube status: column "url" of relation "youtube_data" does not exist
LINE 3: ...lished_at, view_count, like_count, comment_count, url, scrap...
                                                             ^

2025-05-15 19:15:02,891 [INFO] Starting YouTube scraping for region DE...
2025-05-15 19:15:03,245 [INFO] Successfully fetched trending videos from YouTube API
2025-05-15 19:15:03,245 [INFO] Found 50 trending videos
2025-05-15 19:15:05,853 [ERROR] Error during YouTube scraping: column "url" of relation "youtube_data" does not exist
LINE 5:                             url, scraped_at, trending_date
                                    ^

2025-05-15 19:15:05,853 [ERROR] Detailed error:
Traceback (most recent call last):
  File "c:\Users\SofiePischl\Documents\01_HdM\10_ML_OPS\TrendAnalyseSocialMedia\src\scheduler\jobs\youtube_scraper.py", line 233, in scrape_youtube_trending
    execute_values(cur, insert_query, values)
    ~~~~~~~~~~~~~~^^^^^^^^^^^^^^^^^^^^^^^^^^^
  File "C:\Users\SofiePischl\Documents\01_HdM\10_ML_OPS\TrendAnalyseSocialMedia\venv\Lib\site-packages\psycopg2\extras.py", line 1299, in execute_values
    cur.execute(b''.join(parts))
    ~~~~~~~~~~~^^^^^^^^^^^^^^^^^
psycopg2.errors.UndefinedColumn: column "url" of relation "youtube_data" does not exist
LINE 5:                             url, scraped_at, trending_date
                                    ^

2025-05-15 19:15:07,878 [ERROR] Error updating YouTube status: column "url" of relation "youtube_data" does not exist
LINE 3: ...lished_at, view_count, like_count, comment_count, url, scrap...
                                                             ^

2025-05-15 19:15:30,974 [INFO] Starting YouTube scraping for region DE...
2025-05-15 19:15:31,108 [INFO] Successfully fetched trending videos from YouTube API
2025-05-15 19:15:31,108 [INFO] Found 50 trending videos
2025-05-15 19:15:33,698 [INFO] Successfully stored 50 YouTube videos in the database
2025-05-15 19:20:06,128 [INFO] Last scrape was 8.4 minutes ago - waiting
2025-05-15 19:23:31,469 [INFO] Starting YouTube scraping for region DE...
2025-05-15 19:23:31,818 [INFO] Successfully fetched trending videos from YouTube API
2025-05-15 19:23:31,819 [INFO] Found 50 trending videos
2025-05-15 19:23:34,374 [ERROR] Error during YouTube scraping: column "url" of relation "youtube_data" does not exist
LINE 5:                             url, scraped_at, trending_date
                                    ^

2025-05-15 19:23:34,374 [ERROR] Detailed error:
Traceback (most recent call last):
  File "C:\Users\SofiePischl\Documents\01_HdM\10_ML_OPS\TrendAnalyseSocialMedia\src\scheduler\jobs\youtube_scraper.py", line 233, in scrape_youtube_trending
    execute_values(cur, insert_query, values)
    ~~~~~~~~~~~~~~^^^^^^^^^^^^^^^^^^^^^^^^^^^
  File "C:\Users\SofiePischl\Documents\01_HdM\10_ML_OPS\TrendAnalyseSocialMedia\venv\Lib\site-packages\psycopg2\extras.py", line 1299, in execute_values
    cur.execute(b''.join(parts))
    ~~~~~~~~~~~^^^^^^^^^^^^^^^^^
psycopg2.errors.UndefinedColumn: column "url" of relation "youtube_data" does not exist
LINE 5:                             url, scraped_at, trending_date
                                    ^

2025-05-15 19:23:36,494 [ERROR] Error updating YouTube status: column "url" of relation "youtube_data" does not exist
LINE 3: ...lished_at, view_count, like_count, comment_count, url, scrap...
                                                             ^

2025-05-15 19:26:50,348 [INFO] Starting YouTube scraping for region DE...
2025-05-15 19:26:50,495 [INFO] Successfully fetched trending videos from YouTube API
2025-05-15 19:26:50,495 [INFO] Found 50 trending videos
2025-05-15 19:26:53,164 [ERROR] Error during YouTube scraping: column "url" of relation "youtube_data" does not exist
LINE 5:                             url, scraped_at, trending_date
                                    ^

2025-05-15 19:26:53,164 [ERROR] Detailed error:
Traceback (most recent call last):
  File "C:\Users\SofiePischl\Documents\01_HdM\10_ML_OPS\TrendAnalyseSocialMedia\src\scheduler\jobs\youtube_scraper.py", line 199, in scrape_youtube_trending
    PRIMARY KEY (video_id, trending_date)
    ^^^^^^^^^^^^^^^^^^^^^^^^^^^^^^^^^
  File "C:\Users\SofiePischl\Documents\01_HdM\10_ML_OPS\TrendAnalyseSocialMedia\venv\Lib\site-packages\psycopg2\extras.py", line 1299, in execute_values
    cur.execute(b''.join(parts))
    ~~~~~~~~~~~^^^^^^^^^^^^^^^^^
psycopg2.errors.UndefinedColumn: column "url" of relation "youtube_data" does not exist
LINE 5:                             url, scraped_at, trending_date
                                    ^

2025-05-15 19:28:24,073 [INFO] Starting YouTube scraping for region DE...
2025-05-15 19:28:24,201 [INFO] Successfully fetched trending videos from YouTube API
2025-05-15 19:28:24,201 [INFO] Found 50 trending videos
2025-05-15 19:28:26,810 [ERROR] Error during YouTube scraping: column "url" of relation "youtube_data" does not exist
LINE 5:                             url, scraped_at, trending_date
                                    ^

2025-05-15 19:28:26,811 [ERROR] Detailed error:
Traceback (most recent call last):
  File "C:\Users\SofiePischl\Documents\01_HdM\10_ML_OPS\TrendAnalyseSocialMedia\src\scheduler\jobs\youtube_scraper.py", line 233, in scrape_youtube_trending
    execute_values(cur, insert_query, values)
    ~~~~~~~~~~~~~~^^^^^^^^^^^^^^^^^^^^^^^^^^^
  File "C:\Users\SofiePischl\Documents\01_HdM\10_ML_OPS\TrendAnalyseSocialMedia\venv\Lib\site-packages\psycopg2\extras.py", line 1299, in execute_values
    cur.execute(b''.join(parts))
    ~~~~~~~~~~~^^^^^^^^^^^^^^^^^
psycopg2.errors.UndefinedColumn: column "url" of relation "youtube_data" does not exist
LINE 5:                             url, scraped_at, trending_date
                                    ^

2025-05-15 19:28:28,673 [ERROR] Error updating YouTube status: column "url" of relation "youtube_data" does not exist
LINE 3: ...lished_at, view_count, like_count, comment_count, url, scrap...
                                                             ^

2025-05-15 19:30:47,645 [INFO] Starting YouTube scraping for region DE...
2025-05-15 19:30:47,953 [INFO] Successfully fetched trending videos from YouTube API
2025-05-15 19:30:47,953 [INFO] Found 50 trending videos
2025-05-15 19:30:50,591 [INFO] Successfully stored 50 YouTube videos in the database
2025-05-15 19:36:47,748 [INFO] Starting YouTube scraping for region DE...
2025-05-15 19:36:48,036 [INFO] Successfully fetched trending videos from YouTube API
2025-05-15 19:36:48,037 [INFO] Found 50 trending videos
2025-05-15 19:36:50,775 [ERROR] Error during YouTube scraping: column "url" of relation "youtube_data" does not exist
LINE 5:                             url, scraped_at, trending_date
                                    ^

2025-05-15 19:36:50,776 [ERROR] Detailed error:
Traceback (most recent call last):
  File "C:\Users\SofiePischl\Documents\01_HdM\10_ML_OPS\TrendAnalyseSocialMedia\src\scheduler\jobs\youtube_scraper.py", line 199, in scrape_youtube_trending
    PRIMARY KEY (video_id, trending_date)
    ^^^^^^^^^^^^^^^^^^^^^^^^^^^^^^^^^
  File "C:\Users\SofiePischl\Documents\01_HdM\10_ML_OPS\TrendAnalyseSocialMedia\venv\Lib\site-packages\psycopg2\extras.py", line 1299, in execute_values
    cur.execute(b''.join(parts))
    ~~~~~~~~~~~^^^^^^^^^^^^^^^^^
psycopg2.errors.UndefinedColumn: column "url" of relation "youtube_data" does not exist
LINE 5:                             url, scraped_at, trending_date
                                    ^

2025-05-15 19:40:19,445 [INFO] Starting YouTube scraping for region DE...
2025-05-15 19:40:19,665 [INFO] Successfully fetched trending videos from YouTube API
2025-05-15 19:40:19,666 [INFO] Found 50 trending videos
2025-05-15 19:40:22,245 [ERROR] Error during YouTube scraping: column "trending_date" of relation "youtube_data" does not exist
LINE 5:                             url, scraped_at, trending_date
                                                     ^

2025-05-15 19:40:22,246 [ERROR] Detailed error:
Traceback (most recent call last):
  File "C:\Users\SofiePischl\Documents\01_HdM\10_ML_OPS\TrendAnalyseSocialMedia\src\scheduler\jobs\youtube_scraper.py", line 233, in scrape_youtube_trending
    execute_values(cur, insert_query, values)
    ~~~~~~~~~~~~~~^^^^^^^^^^^^^^^^^^^^^^^^^^^
  File "C:\Users\SofiePischl\Documents\01_HdM\10_ML_OPS\TrendAnalyseSocialMedia\venv\Lib\site-packages\psycopg2\extras.py", line 1299, in execute_values
    cur.execute(b''.join(parts))
    ~~~~~~~~~~~^^^^^^^^^^^^^^^^^
psycopg2.errors.UndefinedColumn: column "trending_date" of relation "youtube_data" does not exist
LINE 5:                             url, scraped_at, trending_date
                                                     ^

2025-05-15 19:40:24,181 [ERROR] Error updating YouTube status: column "trending_date" of relation "youtube_data" does not exist
LINE 3: ...ount, like_count, comment_count, url, scraped_at, trending_d...
                                                             ^

2025-05-15 19:42:12,856 [INFO] Starting YouTube scraping for region DE...
2025-05-15 19:42:13,145 [INFO] Successfully fetched trending videos from YouTube API
2025-05-15 19:42:13,145 [INFO] Found 50 trending videos
2025-05-15 19:42:15,773 [ERROR] Error during YouTube scraping: column "trending_date" of relation "youtube_data" does not exist
LINE 5:                             url, scraped_at, trending_date
                                                     ^

2025-05-15 19:42:15,774 [ERROR] Detailed error:
Traceback (most recent call last):
  File "C:\Users\SofiePischl\Documents\01_HdM\10_ML_OPS\TrendAnalyseSocialMedia\src\scheduler\jobs\youtube_scraper.py", line 199, in scrape_youtube_trending
    PRIMARY KEY (video_id, trending_date)
    ^^^^^^^^^^^^^^^^^^^^^^^^^^^^^^^^^
  File "C:\Users\SofiePischl\Documents\01_HdM\10_ML_OPS\TrendAnalyseSocialMedia\venv\Lib\site-packages\psycopg2\extras.py", line 1299, in execute_values
    cur.execute(b''.join(parts))
    ~~~~~~~~~~~^^^^^^^^^^^^^^^^^
psycopg2.errors.UndefinedColumn: column "trending_date" of relation "youtube_data" does not exist
LINE 5:                             url, scraped_at, trending_date
                                                     ^

2025-05-15 19:43:23,557 [INFO] Starting YouTube scraping for region DE...
2025-05-15 19:43:23,966 [INFO] Successfully fetched trending videos from YouTube API
2025-05-15 19:43:23,967 [INFO] Found 50 trending videos
2025-05-15 19:43:26,678 [ERROR] Error during YouTube scraping: column "trending_date" of relation "youtube_data" does not exist
LINE 5:                             url, scraped_at, trending_date
                                                     ^

2025-05-15 19:43:26,679 [ERROR] Detailed error:
Traceback (most recent call last):
  File "c:\Users\SofiePischl\Documents\01_HdM\10_ML_OPS\TrendAnalyseSocialMedia\src\scheduler\jobs\youtube_scraper.py", line 233, in scrape_youtube_trending
    execute_values(cur, insert_query, values)
    ~~~~~~~~~~~~~~^^^^^^^^^^^^^^^^^^^^^^^^^^^
  File "C:\Users\SofiePischl\Documents\01_HdM\10_ML_OPS\TrendAnalyseSocialMedia\venv\Lib\site-packages\psycopg2\extras.py", line 1299, in execute_values
    cur.execute(b''.join(parts))
    ~~~~~~~~~~~^^^^^^^^^^^^^^^^^
psycopg2.errors.UndefinedColumn: column "trending_date" of relation "youtube_data" does not exist
LINE 5:                             url, scraped_at, trending_date
                                                     ^

2025-05-15 19:43:28,733 [ERROR] Error updating YouTube status: column "trending_date" of relation "youtube_data" does not exist
LINE 3: ...ount, like_count, comment_count, url, scraped_at, trending_d...
                                                             ^

2025-05-15 19:43:59,943 [INFO] Starting YouTube scraping for region DE...
2025-05-15 19:44:00,324 [INFO] Successfully fetched trending videos from YouTube API
2025-05-15 19:44:00,325 [INFO] Found 50 trending videos
2025-05-15 19:44:02,279 [ERROR] Error during YouTube scraping: 'trending_date'
2025-05-15 19:44:02,279 [ERROR] Detailed error:
Traceback (most recent call last):
  File "c:\Users\SofiePischl\Documents\01_HdM\10_ML_OPS\TrendAnalyseSocialMedia\src\scheduler\jobs\youtube_scraper.py", line 229, in scrape_youtube_trending
    video["trending_date"]
    ~~~~~^^^^^^^^^^^^^^^^^
KeyError: 'trending_date'
2025-05-15 19:44:04,200 [ERROR] Error updating YouTube status: column "trending_date" of relation "youtube_data" does not exist
LINE 3: ...ount, like_count, comment_count, url, scraped_at, trending_d...
                                                             ^

2025-05-15 19:45:14,268 [INFO] Starting YouTube scraping for region DE...
2025-05-15 19:45:14,399 [INFO] Successfully fetched trending videos from YouTube API
2025-05-15 19:45:14,399 [INFO] Found 50 trending videos
2025-05-15 19:45:15,524 [INFO] Starting YouTube scraping for region DE...
2025-05-15 19:45:15,867 [INFO] Successfully fetched trending videos from YouTube API
2025-05-15 19:45:15,867 [INFO] Found 50 trending videos
2025-05-15 19:45:16,974 [ERROR] Error during YouTube scraping: column "trending_date" of relation "youtube_data" does not exist
LINE 5:                             url, scraped_at, trending_date
                                                     ^

2025-05-15 19:45:16,974 [ERROR] Detailed error:
Traceback (most recent call last):
  File "C:\Users\SofiePischl\Documents\01_HdM\10_ML_OPS\TrendAnalyseSocialMedia\src\scheduler\jobs\youtube_scraper.py", line 233, in scrape_youtube_trending
    logger.info(f"Successfully stored {len(videos)} YouTube videos in the database")
            ^^^^^^^^^^^^^^^^^^^^^^^^^^^^^^^^^^^^^^^^^
  File "C:\Users\SofiePischl\Documents\01_HdM\10_ML_OPS\TrendAnalyseSocialMedia\venv\Lib\site-packages\psycopg2\extras.py", line 1299, in execute_values
    cur.execute(b''.join(parts))
    ~~~~~~~~~~~^^^^^^^^^^^^^^^^^
psycopg2.errors.UndefinedColumn: column "trending_date" of relation "youtube_data" does not exist
LINE 5:                             url, scraped_at, trending_date
                                                     ^

2025-05-15 19:45:17,831 [ERROR] Error during YouTube scraping: syntax error at or near "("
LINE 13:                             PRIMARY KEY (video_id, scraped_a...
                                                 ^

2025-05-15 19:45:17,831 [ERROR] Detailed error:
Traceback (most recent call last):
  File "c:\Users\SofiePischl\Documents\01_HdM\10_ML_OPS\TrendAnalyseSocialMedia\src\scheduler\jobs\youtube_scraper.py", line 185, in scrape_youtube_trending
    cur.execute("""
    ~~~~~~~~~~~^^^^
        CREATE TABLE IF NOT EXISTS youtube_data (
        ^^^^^^^^^^^^^^^^^^^^^^^^^^^^^^^^^^^^^^^^^
    ...<11 lines>...
        )
        ^
    """)
    ^^^^
psycopg2.errors.SyntaxError: syntax error at or near "("
LINE 13:                             PRIMARY KEY (video_id, scraped_a...
                                                 ^

2025-05-15 19:45:19,066 [ERROR] Error updating YouTube status: column "trending_date" of relation "youtube_data" does not exist
LINE 3: ...ount, like_count, comment_count, url, scraped_at, trending_d...
                                                             ^

2025-05-15 19:45:19,881 [ERROR] Error updating YouTube status: column "trending_date" of relation "youtube_data" does not exist
LINE 3: ...ount, like_count, comment_count, url, scraped_at, trending_d...
                                                             ^

2025-05-15 19:46:04,912 [INFO] Starting YouTube scraping for region DE...
2025-05-15 19:46:05,071 [INFO] Successfully fetched trending videos from YouTube API
2025-05-15 19:46:05,072 [INFO] Found 50 trending videos
2025-05-15 19:46:07,690 [INFO] Successfully stored 50 YouTube videos in the database
2025-05-15 19:48:08,721 [WARNING] Error checking last scrape time: syntax error at or near "("
LINE 13:                         PRIMARY KEY (video_id, trending_date...
                                             ^

2025-05-15 19:48:08,722 [INFO] Starting YouTube scraping for region DE...
2025-05-15 19:48:09,251 [INFO] Successfully fetched trending videos from YouTube API
2025-05-15 19:48:09,252 [INFO] Found 50 trending videos
2025-05-15 19:48:11,176 [ERROR] Error during YouTube scraping: syntax error at or near "("
LINE 13:                             PRIMARY KEY (video_id, scraped_a...
                                                 ^

2025-05-15 19:48:11,177 [ERROR] Detailed error:
Traceback (most recent call last):
  File "c:\Users\SofiePischl\Documents\01_HdM\10_ML_OPS\TrendAnalyseSocialMedia\src\scheduler\jobs\youtube_scraper.py", line 184, in scrape_youtube_trending
    cur.execute("""
    ~~~~~~~~~~~^^^^
        CREATE TABLE IF NOT EXISTS youtube_data (
        ^^^^^^^^^^^^^^^^^^^^^^^^^^^^^^^^^^^^^^^^^
    ...<11 lines>...
        )
        ^
    """)
    ^^^^
psycopg2.errors.SyntaxError: syntax error at or near "("
LINE 13:                             PRIMARY KEY (video_id, scraped_a...
                                                 ^

2025-05-15 19:48:13,160 [ERROR] Error updating YouTube status: column "trending_date" of relation "youtube_data" does not exist
LINE 3: ...ount, like_count, comment_count, url, scraped_at, trending_d...
                                                             ^

2025-05-15 19:48:31,352 [WARNING] Error checking last scrape time: syntax error at or near "("
LINE 13:                         PRIMARY KEY (video_id, scraped_at)
                                             ^

2025-05-15 19:48:31,353 [INFO] Starting YouTube scraping for region DE...
2025-05-15 19:48:31,709 [INFO] Successfully fetched trending videos from YouTube API
2025-05-15 19:48:31,709 [INFO] Found 50 trending videos
2025-05-15 19:48:33,620 [ERROR] Error during YouTube scraping: syntax error at or near "("
LINE 13:                             PRIMARY KEY (video_id, scraped_a...
                                                 ^

2025-05-15 19:48:33,621 [ERROR] Detailed error:
Traceback (most recent call last):
  File "c:\Users\SofiePischl\Documents\01_HdM\10_ML_OPS\TrendAnalyseSocialMedia\src\scheduler\jobs\youtube_scraper.py", line 184, in scrape_youtube_trending
    cur.execute("""
    ~~~~~~~~~~~^^^^
        CREATE TABLE IF NOT EXISTS youtube_data (
        ^^^^^^^^^^^^^^^^^^^^^^^^^^^^^^^^^^^^^^^^^
    ...<11 lines>...
        )
        ^
    """)
    ^^^^
psycopg2.errors.SyntaxError: syntax error at or near "("
LINE 13:                             PRIMARY KEY (video_id, scraped_a...
                                                 ^

2025-05-15 19:48:35,475 [ERROR] Error updating YouTube status: column "trending_date" of relation "youtube_data" does not exist
LINE 3: ...ount, like_count, comment_count, url, scraped_at, trending_d...
                                                             ^

2025-05-15 19:48:42,528 [INFO] Starting YouTube scraping for region DE...
2025-05-15 19:48:42,891 [INFO] Successfully fetched trending videos from YouTube API
2025-05-15 19:48:42,891 [INFO] Found 50 trending videos
2025-05-15 19:48:44,840 [ERROR] Error during YouTube scraping: syntax error at or near "("
LINE 13:                             PRIMARY KEY (video_id, scraped_a...
                                                 ^

2025-05-15 19:48:44,841 [ERROR] Detailed error:
Traceback (most recent call last):
  File "c:\Users\SofiePischl\Documents\01_HdM\10_ML_OPS\TrendAnalyseSocialMedia\src\scheduler\jobs\youtube_scraper.py", line 184, in scrape_youtube_trending
    cur.execute("""
    ~~~~~~~~~~~^^^^
        CREATE TABLE IF NOT EXISTS youtube_data (
        ^^^^^^^^^^^^^^^^^^^^^^^^^^^^^^^^^^^^^^^^^
    ...<11 lines>...
        )
        ^
    """)
    ^^^^
psycopg2.errors.SyntaxError: syntax error at or near "("
LINE 13:                             PRIMARY KEY (video_id, scraped_a...
                                                 ^

2025-05-15 19:48:46,787 [ERROR] Error updating YouTube status: column "trending_date" of relation "youtube_data" does not exist
LINE 3: ...ount, like_count, comment_count, url, scraped_at, trending_d...
                                                             ^

2025-05-15 19:50:59,450 [INFO] Starting YouTube scraping for region DE...
2025-05-15 19:50:59,813 [INFO] Successfully fetched trending videos from YouTube API
2025-05-15 19:50:59,814 [INFO] Found 50 trending videos
2025-05-15 19:51:01,686 [ERROR] Error during YouTube scraping: syntax error at or near "("
LINE 13:                             PRIMARY KEY (video_id, scraped_a...
                                                 ^

2025-05-15 19:51:01,687 [ERROR] Detailed error:
Traceback (most recent call last):
  File "c:\Users\SofiePischl\Documents\01_HdM\10_ML_OPS\TrendAnalyseSocialMedia\src\scheduler\jobs\youtube_scraper.py", line 184, in scrape_youtube_trending
    cur.execute("""
    ~~~~~~~~~~~^^^^
        CREATE TABLE IF NOT EXISTS youtube_data (
        ^^^^^^^^^^^^^^^^^^^^^^^^^^^^^^^^^^^^^^^^^
    ...<11 lines>...
        )
        ^
    """)
    ^^^^
psycopg2.errors.SyntaxError: syntax error at or near "("
LINE 13:                             PRIMARY KEY (video_id, scraped_a...
                                                 ^

2025-05-15 19:51:03,619 [ERROR] Error updating YouTube status: column "trending_date" of relation "youtube_data" does not exist
LINE 3: ...ount, like_count, comment_count, url, scraped_at, trending_d...
                                                             ^

2025-05-15 19:52:39,491 [INFO] Starting YouTube scraping for region DE...
2025-05-15 19:52:39,855 [INFO] Successfully fetched trending videos from YouTube API
2025-05-15 19:52:39,856 [INFO] Found 50 trending videos
2025-05-15 19:52:42,475 [ERROR] Error during YouTube scraping: column "trending_date" of relation "youtube_data" does not exist
LINE 5:                             url, scraped_at, trending_date
                                                     ^

2025-05-15 19:52:42,476 [ERROR] Detailed error:
Traceback (most recent call last):
  File "C:\Users\SofiePischl\Documents\01_HdM\10_ML_OPS\TrendAnalyseSocialMedia\src\scheduler\jobs\youtube_scraper.py", line 234, in scrape_youtube_trending
    execute_values(cur, insert_query, values)
    ~~~~~~~~~~~~~~^^^^^^^^^^^^^^^^^^^^^^^^^^^
  File "C:\Users\SofiePischl\Documents\01_HdM\10_ML_OPS\TrendAnalyseSocialMedia\venv\Lib\site-packages\psycopg2\extras.py", line 1299, in execute_values
    cur.execute(b''.join(parts))
    ~~~~~~~~~~~^^^^^^^^^^^^^^^^^
psycopg2.errors.UndefinedColumn: column "trending_date" of relation "youtube_data" does not exist
LINE 5:                             url, scraped_at, trending_date
                                                     ^

2025-05-15 19:52:44,425 [ERROR] Error updating YouTube status: column "trending_date" of relation "youtube_data" does not exist
LINE 3: ...ount, like_count, comment_count, url, scraped_at, trending_d...
                                                             ^

2025-05-15 19:53:31,449 [INFO] Last scrape was 8.1 minutes ago - waiting
2025-05-15 19:55:17,110 [INFO] Starting YouTube scraping for region DE...
2025-05-15 19:55:17,901 [INFO] Successfully fetched trending videos from YouTube API
2025-05-15 19:55:17,902 [INFO] Found 50 trending videos
2025-05-15 19:55:20,516 [INFO] Successfully stored 50 YouTube videos in the database
2025-05-15 19:57:04,626 [INFO] Starting YouTube scraping for region DE...
2025-05-15 19:57:05,019 [INFO] Successfully fetched trending videos from YouTube API
2025-05-15 19:57:05,019 [INFO] Found 50 trending videos
2025-05-15 19:57:07,124 [INFO] Starting YouTube scraping for region DE...
2025-05-15 19:57:07,273 [INFO] Successfully fetched trending videos from YouTube API
2025-05-15 19:57:07,274 [INFO] Found 50 trending videos
2025-05-15 19:57:07,671 [INFO] Successfully stored 50 YouTube videos in the database
2025-05-15 19:57:09,863 [INFO] Successfully stored 50 YouTube videos in the database
2025-05-15 19:57:35,853 [INFO] Last scrape was 0.4 minutes ago - waiting
2025-05-15 20:01:21,533 [INFO] Starting YouTube scraping for region DE...
2025-05-15 20:01:22,193 [INFO] Successfully fetched trending videos from YouTube API
2025-05-15 20:01:22,194 [INFO] Found 50 trending videos
2025-05-15 20:01:24,871 [INFO] Successfully stored 50 YouTube videos in the database
2025-05-15 20:02:09,872 [INFO] Starting YouTube scraping for region DE...
2025-05-15 20:02:10,001 [INFO] Successfully fetched trending videos from YouTube API
2025-05-15 20:02:10,002 [INFO] Found 50 trending videos
2025-05-15 20:02:12,688 [INFO] Successfully stored 50 YouTube videos in the database
2025-05-15 20:06:46,635 [INFO] Starting YouTube scraping for region DE...
2025-05-15 20:06:47,155 [INFO] Successfully fetched trending videos from YouTube API
2025-05-15 20:06:47,156 [INFO] Found 50 trending videos
2025-05-15 20:06:49,038 [ERROR] Error during YouTube scraping: 'trending_date'
2025-05-15 20:06:49,039 [ERROR] Detailed error:
Traceback (most recent call last):
  File "c:\Users\SofiePischl\Documents\01_HdM\10_ML_OPS\TrendAnalyseSocialMedia\src\scheduler\jobs\youtube_scraper.py", line 227, in scrape_youtube_trending
    video["trending_date"]
    ~~~~~^^^^^^^^^^^^^^^^^
KeyError: 'trending_date'
2025-05-15 20:06:50,932 [ERROR] Error updating YouTube status: INSERT has more expressions than target columns
LINE 4: ...le.com', '2025-05-15T20:06:50.380298'::timestamp, '2025-05-1...
                                                             ^

2025-05-15 20:08:21,173 [INFO] Starting YouTube scraping for region DE...
2025-05-15 20:08:21,511 [INFO] Successfully fetched trending videos from YouTube API
2025-05-15 20:08:21,511 [INFO] Found 50 trending videos
2025-05-15 20:08:24,267 [ERROR] Error during YouTube scraping: there is no unique or exclusion constraint matching the ON CONFLICT specification

2025-05-15 20:08:24,268 [ERROR] Detailed error:
Traceback (most recent call last):
  File "c:\Users\SofiePischl\Documents\01_HdM\10_ML_OPS\TrendAnalyseSocialMedia\src\scheduler\jobs\youtube_scraper.py", line 228, in scrape_youtube_trending
    execute_values(cur, insert_query, values)
    ~~~~~~~~~~~~~~^^^^^^^^^^^^^^^^^^^^^^^^^^^
  File "C:\Users\SofiePischl\Documents\01_HdM\10_ML_OPS\TrendAnalyseSocialMedia\venv\Lib\site-packages\psycopg2\extras.py", line 1299, in execute_values
    cur.execute(b''.join(parts))
    ~~~~~~~~~~~^^^^^^^^^^^^^^^^^
psycopg2.errors.InvalidColumnReference: there is no unique or exclusion constraint matching the ON CONFLICT specification

2025-05-15 20:08:26,313 [ERROR] Error updating YouTube status: INSERT has more expressions than target columns
LINE 5: ...le.com', '2025-05-15T20:08:25.723752'::timestamp, '2025-05-1...
                                                             ^

2025-05-15 20:09:03,851 [INFO] Starting YouTube scraping for region DE...
2025-05-15 20:09:04,189 [INFO] Successfully fetched trending videos from YouTube API
2025-05-15 20:09:04,190 [INFO] Found 50 trending videos
2025-05-15 20:09:06,809 [ERROR] Error during YouTube scraping: there is no unique or exclusion constraint matching the ON CONFLICT specification

2025-05-15 20:09:06,810 [ERROR] Detailed error:
Traceback (most recent call last):
  File "c:\Users\SofiePischl\Documents\01_HdM\10_ML_OPS\TrendAnalyseSocialMedia\src\scheduler\jobs\youtube_scraper.py", line 228, in scrape_youtube_trending
    execute_values(cur, insert_query, values)
    ~~~~~~~~~~~~~~^^^^^^^^^^^^^^^^^^^^^^^^^^^
  File "C:\Users\SofiePischl\Documents\01_HdM\10_ML_OPS\TrendAnalyseSocialMedia\venv\Lib\site-packages\psycopg2\extras.py", line 1299, in execute_values
    cur.execute(b''.join(parts))
    ~~~~~~~~~~~^^^^^^^^^^^^^^^^^
psycopg2.errors.InvalidColumnReference: there is no unique or exclusion constraint matching the ON CONFLICT specification

2025-05-15 20:09:08,750 [ERROR] Error updating YouTube status: INSERT has more expressions than target columns
LINE 5: ...le.com', '2025-05-15T20:09:08.176908'::timestamp, '2025-05-1...
                                                             ^

2025-05-15 20:09:53,039 [INFO] Starting YouTube scraping for region DE...
2025-05-15 20:09:53,411 [INFO] Successfully fetched trending videos from YouTube API
2025-05-15 20:09:53,411 [INFO] Found 50 trending videos
2025-05-15 20:09:55,308 [ERROR] Error during YouTube scraping: 'trending_date'
2025-05-15 20:09:55,309 [ERROR] Detailed error:
Traceback (most recent call last):
  File "c:\Users\SofiePischl\Documents\01_HdM\10_ML_OPS\TrendAnalyseSocialMedia\src\scheduler\jobs\youtube_scraper.py", line 227, in scrape_youtube_trending
    video["trending_date"]
    ~~~~~^^^^^^^^^^^^^^^^^
KeyError: 'trending_date'
2025-05-15 20:09:57,253 [ERROR] Error updating YouTube status: INSERT has more expressions than target columns
LINE 4: ...le.com', '2025-05-15T20:09:56.673658'::timestamp, '2025-05-1...
                                                             ^

2025-05-15 20:10:14,606 [INFO] Last scrape was 7.9 minutes ago - waiting
2025-05-15 20:10:57,105 [INFO] YouTube status updated in database
2025-05-15 20:11:39,826 [INFO] YouTube status updated in database
2025-05-15 20:12:49,755 [INFO] YouTube status updated in database
2025-05-15 20:12:55,911 [INFO] Last scrape was 0.1 minutes ago - waiting
2025-05-15 20:13:35,706 [INFO] YouTube status updated in database
2025-05-15 20:13:50,364 [INFO] YouTube status updated in database
2025-05-15 20:13:52,087 [INFO] Starting YouTube scraping for region DE...
2025-05-15 20:13:52,353 [INFO] Successfully fetched trending videos from YouTube API
2025-05-15 20:13:52,354 [INFO] Found 50 trending videos
2025-05-15 20:13:55,077 [INFO] Successfully stored 50 YouTube videos in the database
2025-05-15 20:14:45,929 [INFO] YouTube status updated in database
2025-05-15 20:16:03,946 [INFO] YouTube status updated in database
2025-05-15 20:16:38,821 [INFO] Starting YouTube scraping for region DE...
2025-05-15 20:16:38,953 [INFO] Successfully fetched trending videos from YouTube API
2025-05-15 20:16:38,954 [INFO] Found 50 trending videos
2025-05-15 20:16:41,615 [INFO] Successfully stored 50 YouTube videos in the database
2025-05-15 20:18:58,966 [INFO] Starting YouTube scraping for region DE...
2025-05-15 20:18:59,284 [INFO] Successfully fetched trending videos from YouTube API
2025-05-15 20:18:59,285 [INFO] Found 50 trending videos
2025-05-15 20:19:01,958 [INFO] Successfully stored 50 YouTube videos in the database
2025-05-15 20:25:44,473 [INFO] YouTube status updated in database
2025-05-15 20:35:47,460 [INFO] Starting YouTube scraping for region DE...
2025-05-15 20:35:47,714 [INFO] Successfully fetched trending videos from YouTube API
2025-05-15 20:35:47,714 [INFO] Found 50 trending videos
2025-05-15 20:35:50,347 [INFO] Successfully stored 50 YouTube videos in the database
2025-05-15 20:42:53,773 [INFO] YouTube status updated in database
2025-05-15 20:52:39,077 [INFO] Starting YouTube scraping for region DE...
2025-05-15 20:52:39,381 [INFO] Successfully fetched trending videos from YouTube API
2025-05-15 20:52:39,382 [INFO] Found 50 trending videos
2025-05-15 20:52:42,141 [INFO] Successfully stored 50 YouTube videos in the database
2025-05-15 21:00:15,282 [INFO] YouTube status updated in database
2025-05-15 21:09:28,598 [INFO] Starting YouTube scraping for region DE...
2025-05-15 21:09:28,922 [INFO] Successfully fetched trending videos from YouTube API
2025-05-15 21:09:28,922 [INFO] Found 50 trending videos
2025-05-15 21:09:31,634 [INFO] Successfully stored 50 YouTube videos in the database
2025-05-15 21:17:37,941 [INFO] YouTube status updated in database
2025-05-15 21:26:13,259 [INFO] Starting YouTube scraping for region DE...
2025-05-15 21:26:13,599 [INFO] Successfully fetched trending videos from YouTube API
2025-05-15 21:26:13,600 [INFO] Found 50 trending videos
2025-05-15 21:26:16,333 [INFO] Successfully stored 50 YouTube videos in the database
2025-05-15 21:43:52,150 [INFO] Starting YouTube scraping for region DE...
2025-05-15 21:43:52,519 [INFO] Successfully fetched trending videos from YouTube API
2025-05-15 21:43:52,519 [INFO] Found 50 trending videos
2025-05-15 21:44:39,470 [ERROR] Error during YouTube scraping: connection already closed
2025-05-15 21:44:39,471 [ERROR] Detailed error:
Traceback (most recent call last):
  File "C:\Users\SofiePischl\Documents\01_HdM\10_ML_OPS\TrendAnalyseSocialMedia\src\scheduler\jobs\youtube_scraper.py", line 233, in scrape_youtube_trending
    video["url"],
  File "C:\Users\SofiePischl\Documents\01_HdM\10_ML_OPS\TrendAnalyseSocialMedia\venv\Lib\site-packages\psycopg2\extras.py", line 1299, in execute_values
    cur.execute(b''.join(parts))
    ~~~~~~~~~~~^^^^^^^^^^^^^^^^^
psycopg2.OperationalError: server closed the connection unexpectedly
	This probably means the server terminated abnormally
	before or while processing the request.
server closed the connection unexpectedly
	This probably means the server terminated abnormally
	before or while processing the request.


During handling of the above exception, another exception occurred:

Traceback (most recent call last):
  File "C:\Users\SofiePischl\Documents\01_HdM\10_ML_OPS\TrendAnalyseSocialMedia\src\scheduler\jobs\youtube_scraper.py", line 183, in scrape_youtube_trending
    if videos:
             ^
psycopg2.InterfaceError: connection already closed
2025-05-15 21:45:04,577 [ERROR] Error updating YouTube status: connection already closed
2025-05-15 22:04:21,269 [INFO] Starting YouTube scraping for region DE...
2025-05-15 22:04:21,611 [INFO] Successfully fetched trending videos from YouTube API
2025-05-15 22:04:21,611 [INFO] Found 50 trending videos
2025-05-15 22:04:44,011 [ERROR] Database connection error: connection to server at "caboose.proxy.rlwy.net" (34.1.255.159), port 25158 failed: server closed the connection unexpectedly
	This probably means the server terminated abnormally
	before or while processing the request.
server closed the connection unexpectedly
	This probably means the server terminated abnormally
	before or while processing the request.

2025-05-15 22:04:44,011 [ERROR] Error during YouTube scraping: connection to server at "caboose.proxy.rlwy.net" (34.1.255.159), port 25158 failed: server closed the connection unexpectedly
	This probably means the server terminated abnormally
	before or while processing the request.
server closed the connection unexpectedly
	This probably means the server terminated abnormally
	before or while processing the request.

2025-05-15 22:04:44,011 [ERROR] Detailed error:
Traceback (most recent call last):
  File "C:\Users\SofiePischl\Documents\01_HdM\10_ML_OPS\TrendAnalyseSocialMedia\src\scheduler\jobs\youtube_scraper.py", line 183, in scrape_youtube_trending
    if videos:
             ^
  File "C:\Users\SofiePischl\Documents\01_HdM\10_ML_OPS\TrendAnalyseSocialMedia\src\scheduler\jobs\youtube_scraper.py", line 59, in get_db_connection
    def should_scrape():
                   ^^^^^
  File "C:\Users\SofiePischl\Documents\01_HdM\10_ML_OPS\TrendAnalyseSocialMedia\venv\Lib\site-packages\psycopg2\__init__.py", line 135, in connect
    conn = _connect(dsn, connection_factory=connection_factory, **kwasync)
psycopg2.OperationalError: connection to server at "caboose.proxy.rlwy.net" (34.1.255.159), port 25158 failed: server closed the connection unexpectedly
	This probably means the server terminated abnormally
	before or while processing the request.
server closed the connection unexpectedly
	This probably means the server terminated abnormally
	before or while processing the request.

2025-05-15 22:05:31,226 [INFO] YouTube status updated in database
2025-05-15 22:23:37,639 [INFO] Starting YouTube scraping for region DE...
2025-05-15 22:23:38,004 [INFO] Successfully fetched trending videos from YouTube API
2025-05-15 22:23:38,005 [INFO] Found 50 trending videos
2025-05-15 22:24:07,246 [ERROR] Error during YouTube scraping: connection already closed
2025-05-15 22:24:07,247 [ERROR] Detailed error:
Traceback (most recent call last):
  File "C:\Users\SofiePischl\Documents\01_HdM\10_ML_OPS\TrendAnalyseSocialMedia\src\scheduler\jobs\youtube_scraper.py", line 186, in scrape_youtube_trending
    # Create table if it doesn't exist (redundant but safe)
    ^^^^^^^^^^^^^^^^^^^^^^^^^^^^^^^^^^^^^^^^^^^^^^^^^^^^^^^
    ...<14 lines>...
        )
    
psycopg2.OperationalError: server closed the connection unexpectedly
	This probably means the server terminated abnormally
	before or while processing the request.
server closed the connection unexpectedly
	This probably means the server terminated abnormally
	before or while processing the request.


During handling of the above exception, another exception occurred:

Traceback (most recent call last):
  File "C:\Users\SofiePischl\Documents\01_HdM\10_ML_OPS\TrendAnalyseSocialMedia\src\scheduler\jobs\youtube_scraper.py", line 183, in scrape_youtube_trending
    if videos:
             ^
psycopg2.InterfaceError: connection already closed
2025-05-15 22:24:13,643 [INFO] YouTube status updated in database
2025-05-15 22:41:29,767 [INFO] Starting YouTube scraping for region DE...
2025-05-15 22:41:29,985 [INFO] Successfully fetched trending videos from YouTube API
2025-05-15 22:41:29,985 [INFO] Found 50 trending videos
2025-05-15 22:41:32,611 [INFO] Successfully stored 50 YouTube videos in the database
2025-05-15 22:58:17,871 [INFO] Starting YouTube scraping for region DE...
2025-05-15 22:58:18,157 [INFO] Successfully fetched trending videos from YouTube API
2025-05-15 22:58:18,157 [INFO] Found 50 trending videos
2025-05-15 22:58:20,741 [INFO] Successfully stored 50 YouTube videos in the database
